[2023-12-25 20:36:32,055] {taskinstance.py:1159} INFO - Dependencies all met for <TaskInstance: titanic_pivot.download_titanic_dataset manual__2023-12-25T20:36:28.160005+00:00 [queued]>
[2023-12-25 20:36:32,061] {taskinstance.py:1159} INFO - Dependencies all met for <TaskInstance: titanic_pivot.download_titanic_dataset manual__2023-12-25T20:36:28.160005+00:00 [queued]>
[2023-12-25 20:36:32,061] {taskinstance.py:1356} INFO - 
--------------------------------------------------------------------------------
[2023-12-25 20:36:32,061] {taskinstance.py:1357} INFO - Starting attempt 1 of 2
[2023-12-25 20:36:32,061] {taskinstance.py:1358} INFO - 
--------------------------------------------------------------------------------
[2023-12-25 20:36:32,070] {taskinstance.py:1377} INFO - Executing <Task(PythonOperator): download_titanic_dataset> on 2023-12-25 20:36:28.160005+00:00
[2023-12-25 20:36:32,073] {standard_task_runner.py:52} INFO - Started process 39310 to run task
[2023-12-25 20:36:32,076] {standard_task_runner.py:79} INFO - Running: ['airflow', 'tasks', 'run', 'titanic_pivot', 'download_titanic_dataset', 'manual__2023-12-25T20:36:28.160005+00:00', '--job-id', '6', '--raw', '--subdir', 'DAGS_FOLDER/titanic_dag.py', '--cfg-path', '/tmp/tmpsp6p_0mk', '--error-file', '/tmp/tmpchmgppxn']
[2023-12-25 20:36:32,076] {standard_task_runner.py:80} INFO - Job 6: Subtask download_titanic_dataset
[2023-12-25 20:36:32,130] {task_command.py:369} INFO - Running <TaskInstance: titanic_pivot.download_titanic_dataset manual__2023-12-25T20:36:28.160005+00:00 [running]> on host c975c50309df
[2023-12-25 20:36:32,314] {taskinstance.py:1569} INFO - Exporting the following env vars:
AIRFLOW_CTX_DAG_OWNER=airflow
AIRFLOW_CTX_DAG_ID=titanic_pivot
AIRFLOW_CTX_TASK_ID=download_titanic_dataset
AIRFLOW_CTX_EXECUTION_DATE=2023-12-25T20:36:28.160005+00:00
AIRFLOW_CTX_TRY_NUMBER=1
AIRFLOW_CTX_DAG_RUN_ID=manual__2023-12-25T20:36:28.160005+00:00
[2023-12-25 20:36:34,304] {taskinstance.py:1889} ERROR - Task failed with exception
Traceback (most recent call last):
  File "/usr/local/lib/python3.8/dist-packages/sqlalchemy/engine/base.py", line 1705, in _execute_context
    self.dialect.do_execute(
  File "/usr/local/lib/python3.8/dist-packages/sqlalchemy/engine/default.py", line 716, in do_execute
    cursor.execute(statement, parameters)
psycopg2.errors.InvalidSchemaName: schema "default" does not exist
LINE 2: CREATE TABLE "default".titanic (
                     ^


The above exception was the direct cause of the following exception:

Traceback (most recent call last):
  File "/usr/local/lib/python3.8/dist-packages/airflow/operators/python.py", line 171, in execute
    return_value = self.execute_callable()
  File "/usr/local/lib/python3.8/dist-packages/airflow/operators/python.py", line 189, in execute_callable
    return self.python_callable(*self.op_args, **self.op_kwargs)
  File "/lessons/dags/titanic_dag.py", line 23, in download_titanic_dataset
    df.to_sql('titanic', engine, index=False, if_exists='replace', schema='default')
  File "/usr/local/lib/python3.8/dist-packages/pandas/core/generic.py", line 2963, in to_sql
    return sql.to_sql(
  File "/usr/local/lib/python3.8/dist-packages/pandas/io/sql.py", line 697, in to_sql
    return pandas_sql.to_sql(
  File "/usr/local/lib/python3.8/dist-packages/pandas/io/sql.py", line 1729, in to_sql
    table = self.prep_table(
  File "/usr/local/lib/python3.8/dist-packages/pandas/io/sql.py", line 1628, in prep_table
    table.create()
  File "/usr/local/lib/python3.8/dist-packages/pandas/io/sql.py", line 842, in create
    self._execute_create()
  File "/usr/local/lib/python3.8/dist-packages/pandas/io/sql.py", line 828, in _execute_create
    self.table.create(bind=self.pd_sql.connectable)
  File "/usr/local/lib/python3.8/dist-packages/sqlalchemy/sql/schema.py", line 943, in create
    bind._run_ddl_visitor(ddl.SchemaGenerator, self, checkfirst=checkfirst)
  File "/usr/local/lib/python3.8/dist-packages/sqlalchemy/engine/base.py", line 3008, in _run_ddl_visitor
    conn._run_ddl_visitor(visitorcallable, element, **kwargs)
  File "/usr/local/lib/python3.8/dist-packages/sqlalchemy/engine/base.py", line 2016, in _run_ddl_visitor
    visitorcallable(self.dialect, self, **kwargs).traverse_single(element)
  File "/usr/local/lib/python3.8/dist-packages/sqlalchemy/sql/visitors.py", line 483, in traverse_single
    return meth(obj, **kw)
  File "/usr/local/lib/python3.8/dist-packages/sqlalchemy/sql/ddl.py", line 890, in visit_table
    self.connection.execute(
  File "/usr/local/lib/python3.8/dist-packages/sqlalchemy/engine/base.py", line 1200, in execute
    return meth(self, multiparams, params, _EMPTY_EXECUTION_OPTS)
  File "/usr/local/lib/python3.8/dist-packages/sqlalchemy/sql/ddl.py", line 77, in _execute_on_connection
    return connection._execute_ddl(
  File "/usr/local/lib/python3.8/dist-packages/sqlalchemy/engine/base.py", line 1290, in _execute_ddl
    ret = self._execute_context(
  File "/usr/local/lib/python3.8/dist-packages/sqlalchemy/engine/base.py", line 1748, in _execute_context
    self._handle_dbapi_exception(
  File "/usr/local/lib/python3.8/dist-packages/sqlalchemy/engine/base.py", line 1929, in _handle_dbapi_exception
    util.raise_(
  File "/usr/local/lib/python3.8/dist-packages/sqlalchemy/util/compat.py", line 211, in raise_
    raise exception
  File "/usr/local/lib/python3.8/dist-packages/sqlalchemy/engine/base.py", line 1705, in _execute_context
    self.dialect.do_execute(
  File "/usr/local/lib/python3.8/dist-packages/sqlalchemy/engine/default.py", line 716, in do_execute
    cursor.execute(statement, parameters)
sqlalchemy.exc.ProgrammingError: (psycopg2.errors.InvalidSchemaName) schema "default" does not exist
LINE 2: CREATE TABLE "default".titanic (
                     ^

[SQL: 
CREATE TABLE "default".titanic (
	"Survived" BIGINT, 
	"Pclass" BIGINT, 
	"Name" TEXT, 
	"Sex" TEXT, 
	"Age" FLOAT(53), 
	"Siblings/Spouses Aboard" BIGINT, 
	"Parents/Children Aboard" BIGINT, 
	"Fare" FLOAT(53)
)

]
(Background on this error at: http://sqlalche.me/e/14/f405)
[2023-12-25 20:36:34,621] {taskinstance.py:1395} INFO - Marking task as UP_FOR_RETRY. dag_id=titanic_pivot, task_id=download_titanic_dataset, execution_date=20231225T203628, start_date=20231225T203632, end_date=20231225T203634
[2023-12-25 20:36:34,645] {standard_task_runner.py:92} ERROR - Failed to execute job 6 for task download_titanic_dataset ((psycopg2.errors.InvalidSchemaName) schema "default" does not exist
LINE 2: CREATE TABLE "default".titanic (
                     ^

[SQL: 
CREATE TABLE "default".titanic (
	"Survived" BIGINT, 
	"Pclass" BIGINT, 
	"Name" TEXT, 
	"Sex" TEXT, 
	"Age" FLOAT(53), 
	"Siblings/Spouses Aboard" BIGINT, 
	"Parents/Children Aboard" BIGINT, 
	"Fare" FLOAT(53)
)

]
(Background on this error at: http://sqlalche.me/e/14/f405); 39310)
[2023-12-25 20:36:34,669] {local_task_job.py:156} INFO - Task exited with return code 1
[2023-12-25 20:36:34,702] {local_task_job.py:273} INFO - 0 downstream tasks scheduled from follow-on schedule check
