[2023-12-25 20:59:07,755] {taskinstance.py:1159} INFO - Dependencies all met for <TaskInstance: titanic_pivot.pivot_dataset manual__2023-12-25T20:59:00.360877+00:00 [queued]>
[2023-12-25 20:59:07,762] {taskinstance.py:1159} INFO - Dependencies all met for <TaskInstance: titanic_pivot.pivot_dataset manual__2023-12-25T20:59:00.360877+00:00 [queued]>
[2023-12-25 20:59:07,762] {taskinstance.py:1356} INFO - 
--------------------------------------------------------------------------------
[2023-12-25 20:59:07,762] {taskinstance.py:1357} INFO - Starting attempt 1 of 2
[2023-12-25 20:59:07,762] {taskinstance.py:1358} INFO - 
--------------------------------------------------------------------------------
[2023-12-25 20:59:07,771] {taskinstance.py:1377} INFO - Executing <Task(PythonOperator): pivot_dataset> on 2023-12-25 20:59:00.360877+00:00
[2023-12-25 20:59:07,774] {standard_task_runner.py:52} INFO - Started process 39944 to run task
[2023-12-25 20:59:07,777] {standard_task_runner.py:79} INFO - Running: ['airflow', 'tasks', 'run', 'titanic_pivot', 'pivot_dataset', 'manual__2023-12-25T20:59:00.360877+00:00', '--job-id', '20', '--raw', '--subdir', 'DAGS_FOLDER/titanic_dag.py', '--cfg-path', '/tmp/tmpbluzlahn', '--error-file', '/tmp/tmpowioprs0']
[2023-12-25 20:59:07,777] {standard_task_runner.py:80} INFO - Job 20: Subtask pivot_dataset
[2023-12-25 20:59:07,831] {task_command.py:369} INFO - Running <TaskInstance: titanic_pivot.pivot_dataset manual__2023-12-25T20:59:00.360877+00:00 [running]> on host c975c50309df
[2023-12-25 20:59:07,893] {taskinstance.py:1569} INFO - Exporting the following env vars:
AIRFLOW_CTX_DAG_OWNER=airflow
AIRFLOW_CTX_DAG_ID=titanic_pivot
AIRFLOW_CTX_TASK_ID=pivot_dataset
AIRFLOW_CTX_EXECUTION_DATE=2023-12-25T20:59:00.360877+00:00
AIRFLOW_CTX_TRY_NUMBER=1
AIRFLOW_CTX_DAG_RUN_ID=manual__2023-12-25T20:59:00.360877+00:00
[2023-12-25 20:59:07,957] {taskinstance.py:1889} ERROR - Task failed with exception
Traceback (most recent call last):
  File "/usr/local/lib/python3.8/dist-packages/sqlalchemy/engine/base.py", line 1705, in _execute_context
    self.dialect.do_execute(
  File "/usr/local/lib/python3.8/dist-packages/sqlalchemy/engine/default.py", line 716, in do_execute
    cursor.execute(statement, parameters)
psycopg2.errors.InvalidSchemaName: schema "datasets" does not exist
LINE 2: CREATE TABLE datasets.titanic_pivot (
                     ^


The above exception was the direct cause of the following exception:

Traceback (most recent call last):
  File "/usr/local/lib/python3.8/dist-packages/airflow/operators/python.py", line 171, in execute
    return_value = self.execute_callable()
  File "/usr/local/lib/python3.8/dist-packages/airflow/operators/python.py", line 189, in execute_callable
    return self.python_callable(*self.op_args, **self.op_kwargs)
  File "/lessons/dags/titanic_dag.py", line 35, in pivot_dataset
    df.to_sql('titanic_pivot', engine, index=False, if_exists='replace', schema='datasets')
  File "/usr/local/lib/python3.8/dist-packages/pandas/core/generic.py", line 2963, in to_sql
    return sql.to_sql(
  File "/usr/local/lib/python3.8/dist-packages/pandas/io/sql.py", line 697, in to_sql
    return pandas_sql.to_sql(
  File "/usr/local/lib/python3.8/dist-packages/pandas/io/sql.py", line 1729, in to_sql
    table = self.prep_table(
  File "/usr/local/lib/python3.8/dist-packages/pandas/io/sql.py", line 1628, in prep_table
    table.create()
  File "/usr/local/lib/python3.8/dist-packages/pandas/io/sql.py", line 842, in create
    self._execute_create()
  File "/usr/local/lib/python3.8/dist-packages/pandas/io/sql.py", line 828, in _execute_create
    self.table.create(bind=self.pd_sql.connectable)
  File "/usr/local/lib/python3.8/dist-packages/sqlalchemy/sql/schema.py", line 943, in create
    bind._run_ddl_visitor(ddl.SchemaGenerator, self, checkfirst=checkfirst)
  File "/usr/local/lib/python3.8/dist-packages/sqlalchemy/engine/base.py", line 3008, in _run_ddl_visitor
    conn._run_ddl_visitor(visitorcallable, element, **kwargs)
  File "/usr/local/lib/python3.8/dist-packages/sqlalchemy/engine/base.py", line 2016, in _run_ddl_visitor
    visitorcallable(self.dialect, self, **kwargs).traverse_single(element)
  File "/usr/local/lib/python3.8/dist-packages/sqlalchemy/sql/visitors.py", line 483, in traverse_single
    return meth(obj, **kw)
  File "/usr/local/lib/python3.8/dist-packages/sqlalchemy/sql/ddl.py", line 890, in visit_table
    self.connection.execute(
  File "/usr/local/lib/python3.8/dist-packages/sqlalchemy/engine/base.py", line 1200, in execute
    return meth(self, multiparams, params, _EMPTY_EXECUTION_OPTS)
  File "/usr/local/lib/python3.8/dist-packages/sqlalchemy/sql/ddl.py", line 77, in _execute_on_connection
    return connection._execute_ddl(
  File "/usr/local/lib/python3.8/dist-packages/sqlalchemy/engine/base.py", line 1290, in _execute_ddl
    ret = self._execute_context(
  File "/usr/local/lib/python3.8/dist-packages/sqlalchemy/engine/base.py", line 1748, in _execute_context
    self._handle_dbapi_exception(
  File "/usr/local/lib/python3.8/dist-packages/sqlalchemy/engine/base.py", line 1929, in _handle_dbapi_exception
    util.raise_(
  File "/usr/local/lib/python3.8/dist-packages/sqlalchemy/util/compat.py", line 211, in raise_
    raise exception
  File "/usr/local/lib/python3.8/dist-packages/sqlalchemy/engine/base.py", line 1705, in _execute_context
    self.dialect.do_execute(
  File "/usr/local/lib/python3.8/dist-packages/sqlalchemy/engine/default.py", line 716, in do_execute
    cursor.execute(statement, parameters)
sqlalchemy.exc.ProgrammingError: (psycopg2.errors.InvalidSchemaName) schema "datasets" does not exist
LINE 2: CREATE TABLE datasets.titanic_pivot (
                     ^

[SQL: 
CREATE TABLE datasets.titanic_pivot (
	"Sex" TEXT, 
	"1" BIGINT, 
	"2" BIGINT, 
	"3" BIGINT
)

]
(Background on this error at: http://sqlalche.me/e/14/f405)
[2023-12-25 20:59:07,971] {taskinstance.py:1395} INFO - Marking task as UP_FOR_RETRY. dag_id=titanic_pivot, task_id=pivot_dataset, execution_date=20231225T205900, start_date=20231225T205907, end_date=20231225T205907
[2023-12-25 20:59:07,979] {standard_task_runner.py:92} ERROR - Failed to execute job 20 for task pivot_dataset ((psycopg2.errors.InvalidSchemaName) schema "datasets" does not exist
LINE 2: CREATE TABLE datasets.titanic_pivot (
                     ^

[SQL: 
CREATE TABLE datasets.titanic_pivot (
	"Sex" TEXT, 
	"1" BIGINT, 
	"2" BIGINT, 
	"3" BIGINT
)

]
(Background on this error at: http://sqlalche.me/e/14/f405); 39944)
[2023-12-25 20:59:07,990] {local_task_job.py:156} INFO - Task exited with return code 1
[2023-12-25 20:59:08,019] {local_task_job.py:273} INFO - 0 downstream tasks scheduled from follow-on schedule check
